{
    "dataType": "CVE_RECORD",
    "dataVersion": "5.0",
    "cveMetadata": {
        "state": "PUBLISHED",
        "cveId": "CVE-2022-48565",
        "assignerOrgId": "8254265b-2729-46b6-b9e3-3dfca2d5bfca",
        "assignerShortName": "mitre",
        "dateUpdated": "2023-08-22T15:45:26.713333",
        "dateReserved": "2023-07-23T00:00:00",
        "datePublished": "2023-08-22T00:00:00"
    },
    "containers": {
        "cna": {
            "providerMetadata": {
                "orgId": "8254265b-2729-46b6-b9e3-3dfca2d5bfca",
                "shortName": "mitre",
                "dateUpdated": "2023-08-22T15:45:26.713333"
            },
            "descriptions": [
                {
                    "lang": "en",
                    "value": "An XML External Entity (XXE) issue was discovered in Python through 3.9.1. The plistlib module no longer accepts entity declarations in XML plist files to avoid XML vulnerabilities."
                }
            ],
            "affected": [
                {
                    "vendor": "n/a",
                    "product": "n/a",
                    "versions": [
                        {
                            "version": "n/a",
                            "status": "affected"
                        }
                    ]
                }
            ],
            "references": [
                {
                    "url": "https://bugs.python.org/issue42051"
                }
            ],
            "problemTypes": [
                {
                    "descriptions": [
                        {
                            "type": "text",
                            "lang": "en",
                            "description": "n/a"
                        }
                    ]
                }
            ]
        }
    }
}
