{
    "containers": {
        "cna": {
            "affected": [
                {
                    "product": "n/a",
                    "vendor": "n/a",
                    "versions": [
                        {
                            "status": "affected",
                            "version": "n/a"
                        }
                    ]
                }
            ],
            "descriptions": [
                {
                    "lang": "en",
                    "value": "An issue was discovered in py-lmdb 0.97. mdb_node_del does not validate a memmove in the case of an unexpected node->mn_hi, leading to an invalid write operation. NOTE: this outcome occurs when accessing a data.mdb file supplied by an attacker."
                }
            ],
            "problemTypes": [
                {
                    "descriptions": [
                        {
                            "description": "n/a",
                            "lang": "en",
                            "type": "text"
                        }
                    ]
                }
            ],
            "providerMetadata": {
                "dateUpdated": "2019-10-12T19:40:05",
                "orgId": "8254265b-2729-46b6-b9e3-3dfca2d5bfca",
                "shortName": "mitre"
            },
            "references": [
                {
                    "tags": [
                        "x_refsource_MISC"
                    ],
                    "url": "https://github.com/TeamSeri0us/pocs/tree/master/lmdb/lmdb%20memory%20corruption%20vuln"
                }
            ]
        }
    },
    "cveMetadata": {
        "assignerOrgId": "8254265b-2729-46b6-b9e3-3dfca2d5bfca",
        "assignerShortName": "mitre",
        "cveId": "CVE-2019-16226",
        "datePublished": "2019-09-11T14:47:13",
        "dateReserved": "2019-09-11T00:00:00",
        "dateUpdated": "2019-10-12T19:40:05",
        "state": "PUBLISHED"
    },
    "dataType": "CVE_RECORD",
    "dataVersion": "5.0"
}
