{
    "containers": {
        "cna": {
            "affected": [
                {
                    "product": "DataPower Gateway",
                    "vendor": "IBM",
                    "versions": [
                        {
                            "status": "affected",
                            "version": "2018.4.1.0"
                        },
                        {
                            "status": "affected",
                            "version": "10.0.1.0"
                        },
                        {
                            "status": "affected",
                            "version": "10.0.1.4"
                        },
                        {
                            "status": "affected",
                            "version": "2018.4.1.17"
                        }
                    ]
                }
            ],
            "datePublic": "2022-05-16T00:00:00",
            "descriptions": [
                {
                    "lang": "en",
                    "value": "IBM DataPower Gateway 10.0.1.0 through 10.0.1.4 and 2018.4.1.0 through 2018.4.1.17 could allow a remote user to cause a temporary denial of service by sending invalid HTTP requests. IBM X-Force ID: 192906."
                }
            ],
            "metrics": [
                {
                    "cvssV3_0": {
                        "attackComplexity": "LOW",
                        "attackVector": "NETWORK",
                        "availabilityImpact": "LOW",
                        "baseScore": 5.3,
                        "baseSeverity": "MEDIUM",
                        "confidentialityImpact": "NONE",
                        "exploitCodeMaturity": "UNPROVEN",
                        "integrityImpact": "NONE",
                        "privilegesRequired": "NONE",
                        "remediationLevel": "OFFICIAL_FIX",
                        "reportConfidence": "CONFIRMED",
                        "scope": "UNCHANGED",
                        "temporalScore": 4.6,
                        "temporalSeverity": "MEDIUM",
                        "userInteraction": "NONE",
                        "vectorString": "CVSS:3.0/PR:N/A:L/I:N/AV:N/C:N/S:U/UI:N/AC:L/RC:C/RL:O/E:U",
                        "version": "3.0"
                    }
                }
            ],
            "problemTypes": [
                {
                    "descriptions": [
                        {
                            "description": "Denial of Service",
                            "lang": "en",
                            "type": "text"
                        }
                    ]
                }
            ],
            "providerMetadata": {
                "dateUpdated": "2022-05-17T16:25:18",
                "orgId": "9a959283-ebb5-44b6-b705-dcc2bbced522",
                "shortName": "ibm"
            },
            "references": [
                {
                    "tags": [
                        "x_refsource_CONFIRM"
                    ],
                    "url": "https://www.ibm.com/support/pages/node/6586526"
                },
                {
                    "name": "ibm-datapower-cve20204994-dos (192906)",
                    "tags": [
                        "vdb-entry",
                        "x_refsource_XF"
                    ],
                    "url": "https://exchange.xforce.ibmcloud.com/vulnerabilities/192906"
                }
            ]
        }
    },
    "cveMetadata": {
        "assignerOrgId": "9a959283-ebb5-44b6-b705-dcc2bbced522",
        "assignerShortName": "ibm",
        "cveId": "CVE-2020-4994",
        "dateReserved": "2019-12-30T00:00:00",
        "dateUpdated": "2022-05-17T16:25:18",
        "state": "PUBLISHED",
        "datePublished": "2022-05-17T16:25:18.615789Z"
    },
    "dataType": "CVE_RECORD",
    "dataVersion": "5.0"
}
